Workbook

Sheet Mapato 2023
A1: KANISA LA KIINJILI LA KILUTHERI TANZANIA
A2: DAYOSISI YA MASHARIKI NA PWANI- JIMBO LA MAGHARIBI
A3: USHARIKA WA MAKABE -MTAA WA AGAPE
A4: TAARIFA YA FEDHA- MAPATO JANUARI -DESEMBA 2022
A5: SN | B5: SADAKA | C5: 45292 | D5: 45298 | E5: 45305 | F5: 45312 | G5: 1/28/202 | H5: 45326 | I5: 44969 | J5: 45340 | K5: 45347 | L5: 45354 | M5: 44995 | N5: 45368 | O5: 45379 | P5: 45380 | Q5: 45382 | R5: 45017 | S5: 45389 | T5: 45030 | U5: 45037 | V5: 45410 | W5: 45417 | X5: 45058 | Y5: 45431 | Z5: 45438 | AA5: 45445 | AB5: 45452 | AC5: 45459 | AD5: 45109 | AE5: 45116 | AF5: 44766 | AG5: 45123 | AH5: 45130 | AI5: 45137 | AJ5: 45144 | AK5: 45151 | AL5: 45158 | AM5: 27-agu-23 | AN5: 44822 | AO5: 44829 | AP5: 44836 | AQ5: 44843 | AR5: 44850 | AS5: 44857 | AT5: 44864 | AU5: 44871 | AV5: 44878 | AW5: 44885 | AX5: 44892 | AY5: 44899 | AZ5: 44906 | BA5: 44913 | BB5: 44920 | BC5: 44921 | BD5: JUMLA
A6: M0001 | B6: SADAKA YA MWAKA MPYA | C6: 615350 | E6: 0 | P6: 0 | S6: 0 | T6: 0 | V6: 242650 | W6: - | X6: 0 | Y6: 0 | Z6: 0 | AA6: 0 | AB6: 0 | AC6: 0 | AD6: 0 | AE6: 0 | AF6: 0 | AG6: 0 | AH6: 0 | AI6: 0 | AJ6: 0 | AK6: 0 | AL6: 0 | AM6: 0 | AN6: 0 | AO6: 0 | AP6: 0 | AQ6: 0 | AR6: 0 | AS6: 0 | AT6: 0 | AU6: 0 | AV6: 0 | AW6: 0 | AX6: 0 | AY6: 0 | AZ6: 0 | BA6: 0 | BB6: 0 | BC6: 0 | BD6: =SUM(C6:BC6) -> 858000
A7: M0002 | B7: SHUKRANI YA WIKI (kawaida) na colect | C7: 204650 | D7: 143650 | E7: 343950 | F7: 205250 | G7: 283200 | H7: 370500 | I7: 340600 | J7: 400600 | K7: 285850 | L7: 324500 | M7: 298000 | N7: 319650 | P7: 0 | S7: 290500 | T7: 189700 | U7: 310500 | V7: 301500 | W7: 288750 | X7: 307000 | Y7: 313350 | Z7: 320200 | AA7: 336100 | AB7: 324850 | AC7: 359750 | AD7: 0 | AE7: 0 | AF7: 0 | AG7: 0 | AH7: 0 | AI7: 0 | AJ7: 0 | AK7: 0 | AL7: 0 | AM7: 0 | AN7: 0 | AO7: 0 | AP7: 0 | AQ7: 0 | AR7: 0 | AS7: 0 | AT7: 0 | AU7: 0 | AV7: 0 | AW7: 0 | AX7: 0 | AY7: 0 | AZ7: 0 | BA7: 0 | BB7: 0 | BC7: 0 | BD7: =SUM(C7:BC7) -> 6862600
A8: M0003 | B8: SADAKA YA AHADI | C8: 0 | D8: 131000 | E8: 313000 | F8: 257000 | G8: 262700 | H8: 376000 | I8: 257000 | J8: 326700 | K8: 327900 | L8: 360850 | M8: 394500 | N8: 422500 | P8: 0 | Q8: 492800 | S8: 344200 | T8: 256000 | U8: 405600 | V8: 51000 | W8: 357000 | X8: 361200 | Y8: 390100 | Z8: 408100 | AA8: 388000 | AB8: 333700 | AC8: 397000 | AD8: 0 | AE8: 0 | AF8: 0 | AG8: 0 | AH8: 0 | AI8: 0 | AJ8: 0 | AK8: 0 | AL8: 0 | AM8: 0 | AN8: 0 | AO8: 0 | AP8: 0 | AQ8: 0 | AR8: 0 | AS8: 0 | AT8: 0 | AU8: 0 | AV8: 0 | AW8: 0 | AX8: 0 | AY8: 0 | AZ8: 0 | BA8: 0 | BB8: 0 | BC8: 0 | BD8: =SUM(C8:BC8) -> 7613850
A9: M0004 | B9: SHULE YA JUMAPILI | C9: 0 | D9: 0 | E9: 38900 | F9: 20500 | G9: 37400 | H9: 49400 | I9: 56600 | J9: 48350 | K9: 55850 | L9: 54900 | M9: 51350 | N9: 57000 | P9: 0 | Q9: 103050 | S9: 45250 | T9: 30550 | U9: 53500 | V9: 269800 | W9: 70500 | X9: 51750 | Y9: 48100 | Z9: 57800 | AA9: 47800 | AB9: 42400 | AC9: 55750 | AD9: 0 | AE9: 0 | AF9: 0 | AG9: 0 | AH9: 0 | AI9: 0 | AJ9: 0 | AK9: 0 | AL9: 0 | AM9: 0 | AN9: 0 | AO9: 0 | AP9: 0 | AQ9: 0 | AR9: 0 | AS9: 0 | AT9: 0 | AU9: 0 | AV9: 0 | AW9: 0 | AX9: 0 | AY9: 0 | AZ9: 0 | BA9: 0 | BB9: 0 | BC9: 0 | BD9: =SUM(C9:BC9) -> 1346500
A10: M0005 | B10: SADAKA YA MAVUNO | C10: 0 | D10: 0 | E10: 0 | F10: 0 | H10: 0 | I10: 0 | J10: 0 | L10: 0 | M10: 0 | P10: 0 | Q10: 0 | S10: 0 | T10: 295000 | U10: 0 | V10: 166000 | X10: 0 | Y10: 0 | Z10: 205000 | AA10: 0 | AD10: 0 | AE10: 0 | AF10: 0 | AG10: 0 | AH10: 0 | AI10: 0 | AJ10: 0 | AK10: 0 | AL10: 0 | AM10: 0 | AN10: 0 | AO10: 0 | AP10: 0 | AQ10: 0 | AR10: 0 | AS10: 0 | AT10: 0 | AU10: 0 | AV10: 0 | AW10: 0 | AX10: 0 | AY10: 0 | AZ10: 0 | BA10: 0 | BB10: 0 | BC10: 0 | BD10: =SUM(C10:BC10) -> 666000
A11: M0006 | B11: SADAKA YA PASAKA/kupaa | C11: 0 | D11: 0 | E11: 0 | F11: 0 | G11: 0 | H11: 0 | I11: 0 | J11: 65100 | K11: 0 | L11: 20000 | M11: 19000 | N11: 10500 | P11: 138050 | Q11: 1073400 | R11: 145650 | S11: 0 | T11: 150200 | U11: 0 | V11: 230000 | W11: 0 | X11: 46200 | Y11: 0 | Z11: 0 | AA11: 0 | AC11: 0 | AD11: 0 | AE11: 0 | AF11: 0 | AG11: 0 | AH11: 0 | AI11: 0 | AJ11: 0 | AK11: 0 | AL11: 0 | AM11: 0 | AN11: 0 | AO11: 0 | AP11: 0 | AQ11: 0 | AR11: 0 | AS11: 0 | AT11: 0 | AU11: 0 | AV11: 0 | AW11: 0 | AX11: 0 | AY11: 0 | AZ11: 0 | BA11: 0 | BB11: 0 | BC11: 0 | BD11: =SUM(C11:BC11) -> 1898100
A12: M0007 | B12: SADAKA YA SHUKRANI AINA ZOTE | D12: 184500 | E12: 369450 | F12: 500000 | G12: 157000 | I12: 292250 | J12: 405500 | K12: 337500 | L12: 16800 | M12: 258500 | N12: 0 | Q12: 400500 | S12: 100500 | T12: 0 | U12: 138550 | W12: 39500 | X12: 103300 | Y12: 0 | Z12: 150000 | AA12: 50000 | AB12: 167800 | AC12: 170500 | AD12: 0 | AE12: 0 | AF12: 0 | AG12: 0 | AH12: 0 | AI12: 0 | AJ12: 0 | AK12: 0 | AL12: 0 | AM12: 0 | AN12: 0 | AO12: 0 | AP12: 0 | AQ12: 0 | AR12: 0 | AS12: 0 | AT12: 0 | AU12: 0 | AV12: 0 | AW12: 0 | AX12: 0 | AY12: 0 | AZ12: 0 | BA12: 0 | BB12: 0 | BC12: 0 | BD12: =SUM(C12:BC12) -> 3842150
A13: M0012 | B13: SHUKRANI YA CCB | D13: 0 | E13: 0 | F13: 0 | G13: 0 | H13: 166700 | I13: 0 | J13: 0 | K13: 0 | M13: 0 | O13: 55600 | P13: 0 | Q13: 0 | R13: 31700 | S13: 0 | T13: 0 | AA13: 103100 | AD13: 0 | AE13: 0 | AF13: 0 | AG13: 0 | AH13: 0 | AI13: 0 | AJ13: 0 | AK13: 0 | AL13: 0 | AM13: 0 | AN13: 0 | AO13: 0 | AP13: 0 | AQ13: 0 | AR13: 0 | AS13: 0 | AT13: 0 | AU13: 0 | AV13: 0 | AW13: 0 | AX13: 0 | AY13: 0 | AZ13: 0 | BA13: 0 | BB13: 0 | BC13: 0 | BD13: =SUM(C13:BC13) -> 357100
A14: M0008 | B14: SADAKA YA UBATIZO | D14: 0 | E14: 0 | F14: 0 | G14: 0 | I14: 0 | J14: 0 | K14: 0 | L14: 0 | M14: 0 | O14: 0 | Q14: 0 | R14: 66000 | S14: 0 | T14: 0 | AD14: 0 | AE14: 0 | AF14: 0 | AG14: 0 | AH14: 0 | AI14: 0 | AJ14: 0 | AK14: 0 | AL14: 0 | AM14: 0 | AN14: 0 | AO14: 0 | AP14: 0 | AQ14: 0 | AR14: 0 | AS14: 0 | AT14: 0 | AU14: 0 | AV14: 0 | AW14: 0 | AX14: 0 | AY14: 0 | AZ14: 0 | BA14: 0 | BB14: 0 | BC14: 0 | BD14: =SUM(C14:BC14) -> 66000
A15: M0009 | B15: SHUKRANI YA KIPAIMARA | D15: 0 | E15: 0 | F15: 0 | G15: 0 | I15: 0 | J15: 0 | K15: 0 | L15: 0 | M15: 0 | O15: 0 | Q15: 0 | S15: 0 | T15: 0 | AA15: 20000 | AD15: 0 | AE15: 0 | AF15: 0 | AG15: 0 | AH15: 0 | AI15: 0 | AJ15: 0 | AK15: 0 | AL15: 0 | AM15: 0 | AN15: 0 | AO15: 0 | AP15: 0 | AQ15: 0 | AR15: 0 | AS15: 0 | AT15: 0 | AU15: 0 | AV15: 0 | AW15: 0 | AX15: 0 | AY15: 0 | AZ15: 0 | BA15: 0 | BB15: 0 | BC15: 0 | BD15: =SUM(C15:BC15) -> 20000
A16: M0010 | B16: SHUKRANI YA NDOA | D16: 0 | E16: 0 | F16: 0 | G16: 0 | H16: 0 | I16: 0 | J16: 0 | K16: 0 | M16: 0 | O16: 0 | Q16: 0 | S16: 0 | T16: 0 | AD16: 0 | AE16: 0 | AF16: 0 | AG16: 0 | AH16: 0 | AI16: 0 | AJ16: 0 | AK16: 0 | AL16: 0 | AM16: 0 | AN16: 0 | AO16: 0 | AP16: 0 | AQ16: 0 | AR16: 0 | AS16: 0 | AT16: 0 | AU16: 0 | AV16: 0 | AW16: 0 | AX16: 0 | AY16: 0 | AZ16: 0 | BA16: 0 | BB16: 0 | BC16: 0 | BD16: =SUM(C16:BC16) -> 0
A17: M0011 | B17: SADAKA FUNGU LA KUMI | C17: 292000 | D17: 212300 | E17: 34000 | F17: 78700 | G17: 2054150 | H17: 1610600 | J17: 0 | K17: 141000 | L17: 2936600 | M17: 947000 | N17: 26000 | Q17: 2292150 | S17: 1346900 | T17: 72000 | W17: 1405900 | X17: 65000 | Y17: 154000 | Z17: 2274300 | AA17: 928050 | AB17: 122000 | AC17: 17000 | AD17: 0 | AE17: 0 | AF17: 0 | AG17: 0 | AH17: 0 | AI17: 0 | AJ17: 0 | AK17: 0 | AL17: 0 | AM17: 0 | AN17: 0 | AO17: 0 | AP17: 0 | AQ17: 0 | AR17: 0 | AS17: 0 | AT17: 0 | AU17: 0 | AV17: 0 | AW17: 0 | AX17: 0 | AY17: 0 | AZ17: 0 | BA17: 0 | BB17: 0 | BC17: 0 | BD17: =SUM(C17:BC17) -> 17009650
A18: M0013 | B18: SADAKA YA JENGO | D18: 0 | E18: 255850 | F18: 253500 | G18: 353600 | H18: 358150 | I18: 295000 | J18: 391750 | K18: 349200 | L18: 427000 | M18: 334600 | N18: 378000 | O18: 0 | Q18: 432700 | S18: 257000 | T18: 313500 | U18: 409500 | W18: 384100 | X18: 363400 | Y18: 378000 | Z18: 413000 | AA18: 484000 | AB18: 339050 | AC18: 447000 | AD18: 0 | AE18: 0 | AF18: 0 | AG18: 0 | AH18: 0 | AI18: 0 | AJ18: 0 | AK18: 0 | AL18: 0 | AM18: 0 | AN18: 0 | AO18: 0 | AP18: 0 | AQ18: 0 | AR18: 0 | AS18: 0 | AT18: 0 | AU18: 0 | AV18: 0 | AW18: 0 | AX18: 0 | AY18: 0 | AZ18: 0 | BA18: 0 | BB18: 0 | BC18: 0 | BD18: =SUM(C18:BC18) -> 7617900
A19: M0014 | B19: MICHANGO MBALIMBALI | C19: 0 | D19: 122400 | E19: 0 | F19: 0 | G19: 0 | H19: 0 | I19: 0 | J19: 0 | K19: 0 | L19: 0 | M19: 0 | P19: 0 | Q19: 0 | T19: 0 | U19: 0 | V19: 295000 | W19: 0 | X19: 0 | Y19: 0 | Z19: 0 | AA19: 0 | AB19: 0 | AC19: 0 | AD19: 0 | AE19: 0 | AF19: 0 | AG19: 0 | AH19: 0 | AI19: 0 | AJ19: 0 | AK19: 0 | AL19: 0 | AM19: 0 | AN19: 0 | AO19: 0 | AP19: 0 | AQ19: 0 | AR19: 0 | AS19: 0 | AT19: 0 | AU19: 0 | AV19: 0 | AW19: 0 | AX19: 0 | AY19: 0 | AZ19: 0 | BA19: 0 | BB19: 0 | BC19: 0 | BD19: =SUM(C19:BC19) -> 417400
A20: M0015 | B20: SADAKA YA NYUMBA KWA NYUMBA | C20: 0 | D20: 77850 | E20: 250900 | F20: 109300 | G20: 260000 | H20: 266000 | I20: 277850 | J20: 259050 | K20: 326350 | L20: 235850 | M20: 298750 | N20: 261450 | P20: 0 | Q20: 286900 | S20: 247150 | T20: 298000 | U20: 281100 | V20: 629750 | W20: 252150 | X20: 287500 | Y20: 289200 | Z20: 245500 | AA20: 288250 | AB20: 248250 | AC20: 229650 | AD20: 0 | AE20: 0 | AF20: 0 | AG20: 0 | AH20: 0 | AI20: 0 | AJ20: 0 | AK20: 0 | AL20: 0 | AM20: 0 | AN20: 0 | AO20: 0 | AP20: 0 | AQ20: 0 | AR20: 0 | AS20: 0 | AT20: 0 | AU20: 0 | AV20: 0 | AW20: 0 | AX20: 0 | AY20: 0 | AZ20: 0 | BA20: 0 | BB20: 0 | BC20: 0 | BD20: =SUM(C20:BC20) -> 6206750
A21: M0016 | B21: SADAKA YA MORNING & EVENING GLORY | C21: 0 | D21: 0 | E21: 0 | F21: 0 | G21: 0 | H21: 0 | I21: 0 | J21: 0 | K21: 0 | L21: 0 | M21: 0 | O21: 0 | Q21: 0 | T21: 0 | AD21: 0 | AE21: 0 | AF21: 0 | AG21: 0 | AH21: 0 | AI21: 0 | AJ21: 0 | AK21: 0 | AL21: 0 | AM21: 0 | AN21: 0 | AO21: 0 | AP21: 0 | AQ21: 0 | AR21: 0 | AS21: 0 | AT21: 0 | AU21: 0 | AV21: 0 | AW21: 0 | AX21: 0 | AY21: 0 | AZ21: 0 | BA21: 0 | BB21: 0 | BC21: 0 | BD21: =SUM(C21:BC21) -> 0
A22: M0017 | B22: HARAMBEE na mnada | C22: 0 | D22: 0 | E22: 0 | F22: 27200 | G22: 0 | H22: 0 | I22: 8600 | J22: 0 | L22: 0 | M22: 0 | Q22: 0 | T22: 0 | AD22: 0 | AE22: 0 | AF22: 0 | AG22: 0 | AH22: 0 | AI22: 0 | AJ22: 0 | AK22: 0 | AL22: 0 | AM22: 0 | AN22: 0 | AO22: 0 | AP22: 0 | AQ22: 0 | AR22: 0 | AS22: 0 | AT22: 0 | AU22: 0 | AV22: 0 | AW22: 0 | AX22: 0 | AY22: 0 | AZ22: 0 | BA22: 0 | BB22: 0 | BC22: 0 | BD22: =SUM(C22:BC22) -> 35800
A23: M0018 | B23: SADAKA YA MFUKO WA ELIMU | C23: 0 | D23: 9000 | E23: 26000 | F23: 32800 | G23: 16500 | H23: 21000 | I23: 41000 | J23: 78500 | K23: 60500 | L23: 34100 | M23: 22500 | N23: 31100 | Q23: 20600 | S23: 39700 | T23: 27000 | U23: 29200 | W23: 21500 | X23: 30800 | Y23: 49500 | Z23: 36500 | AA23: 28450 | AB23: 34000 | AC23: 35100 | AD23: 0 | AE23: 0 | AF23: 0 | AG23: 0 | AH23: 0 | AI23: 0 | AJ23: 0 | AK23: 0 | AL23: 0 | AM23: 0 | AN23: 0 | AO23: 0 | AP23: 0 | AQ23: 0 | AR23: 0 | AS23: 0 | AT23: 0 | AU23: 0 | AV23: 0 | AW23: 0 | AX23: 0 | AY23: 0 | AZ23: 0 | BA23: 0 | BB23: 0 | BC23: 0 | BD23: =SUM(C23:BC23) -> 725350
A24: M0019 | B24: SADAKA MAALUM- MAKAO MAKUU, VIJANA, KAZI ZA MISIONI,AKINA MAMA, VYAMA VYA INJILI, MSAMARIA MWEMA | M24: 112650 | N24: 153000 | P24: 0 | Q24: 0 | S24: 154200 | U24: 20000 | AC24: 156250 | AD24: 0 | AE24: 0 | AF24: 0 | AG24: 0 | AH24: 0 | AI24: 0 | AJ24: 0 | AK24: 0 | AL24: 0 | AM24: 0 | AN24: 0 | AO24: 0 | AP24: 0 | AQ24: 0 | AR24: 0 | AS24: 0 | AT24: 0 | AU24: 0 | AV24: 0 | AW24: 0 | AX24: 0 | AY24: 0 | AZ24: 0 | BA24: 0 | BB24: 0 | BC24: 0 | BD24: =SUM(C24:BC24) -> 596100
A25: M0020 | B25: SADAKA ZA KAZI ZA UMOJA _JIMBO NA DAYOSISI | AD25: 0 | AE25: 0 | AF25: 0 | AG25: 0 | AH25: 0 | AI25: 0 | AJ25: 0 | AK25: 0 | AL25: 0 | AM25: 0 | AN25: 0 | AO25: 0 | AP25: 0 | AQ25: 0 | AR25: 0 | AS25: 0 | AT25: 0 | AU25: 0 | AV25: 0 | AW25: 0 | AX25: 0 | AY25: 0 | AZ25: 0 | BA25: 0 | BB25: 0 | BC25: 0 | BD25: =SUM(C25:BC25) -> 0
A26: M0021 | B26: SADAKA YA KRISMAS | D26: 0 | I26: 0 | L26: 0 | AC26: 0 | AD26: 0 | AE26: 0 | AF26: 0 | AG26: 0 | AH26: 0 | AI26: 0 | AJ26: 0 | AK26: 0 | AL26: 0 | AM26: 0 | AN26: 0 | AO26: 0 | AP26: 0 | AQ26: 0 | AR26: 0 | AS26: 0 | AT26: 0 | AU26: 0 | AV26: 0 | AW26: 0 | AX26: 0 | AY26: 0 | AZ26: 0 | BA26: 0 | BB26: 0 | BC26: 0 | BD26: =SUM(C26:BC26) -> 0
B27: JUMLA (TSHS.) | C27: =SUM(C6:C26) -> 1112000 | D27: =SUM(D6:D26) -> 880700 | E27: =SUM(E6:E26) -> 1632050 | F27: =SUM(F6:F26) -> 1484250 | G27: =SUM(G6:G26) -> 3424550 | H27: =SUM(H6:H26) -> 3218350 | I27: =SUM(I6:I26) -> 1568900 | J27: =SUM(J6:J26) -> 1975550 | ... Q27: =SUM(Q6:Q26) -> 5102100 | R27: =SUM(R7:R26) -> 243350 | S27: =SUM(S6:S26) -> 2825400 | T27: =SUM(T6:T26) -> 1631950 | U27: =SUM(U6:U26) -> 1647950 | V27: =SUM(V6:V26) -> 2185700 | W27: =SUM(W6:W26) -> 2819400 | X27: =SUM(X6:X26) -> 1616150 | Y27: =SUM(Y6:Y26) -> 1622250 | Z27: =SUM(Z6:Z26) -> 4110400 | ... BC27: =SUM(BC6:BC26) -> 0 | BD27: =SUM(C27:BC27) -> 56139250

Sheet Sheet2

Sheet SUMMARY 22
A1: KANISA LA KIINJILI LA KILUTHERI TANZANIA | G1: S/N | H1: SADAKA NA MICHANGO MBALIMBALI | I1: 2022 | J1: 2021 | K1: ONGEZEKO | L1: % YA Ongezeko/ Pungufu
A2: DAYOSISI YA MASHARIKI NA PWANI- JIMBO LA MAGHARIBI
A3: USHARIKA WA MAKABE -MTAA WA AGAPE | K3: /PUNGUFU
A4: TAARIFA YA FEDHA- MAPATO JANUARI -DISEMBA 2022 | I4: TSHS | J4: TSHS | K4: TSHS
A5: SN | B5: SADAKA | C5: JUMLA | G5: M0001 | H5: SADAKA YA MWAKA MPYA | I5: =C6 -> 858000 | J5: 13136620 | K5: =I5-J5 -> -12278620 | L5: =K5/J5 -> -0.9346864
A6: M0001 | B6: SHUKRANI YA WIKI | C6: ='Mapato 2023'!BD6 -> 858000 | G6: M0002 | H6: SHUKRANI YA WIKI (kawaida) na colect | I6: =C7 -> 6862600 | J6: 12817580 | K6: =I6-J6 -> -5954980 | L6: =K6/J6 -> -0.46459472
A7: M0002 | B7: AHADI | C7: ='Mapato 2023'!BD7 -> 6862600 | G7: M0003 | H7: SADAKA YA AHADI | I7: =C8 -> 7613850 | J7: 2159900 | K7: =I7-J7 -> 5453950 | L7: =K7/J7 -> 2.5250938
A8: M0003 | B8: SHULE YA JUMAPILI | C8: ='Mapato 2023'!BD8 -> 7613850 | G8: M0004 | H8: SHULE YA JUMAPILI | I8: =C9 -> 1346500 | J8: 4041600 | K8: =I8-J8 -> -2695100 | L8: =K8/J8 -> -0.66683987
A9: M0004 | B9: SHUKRANI YA PEKEE | C9: ='Mapato 2023'!BD9 -> 1346500 | G9: M0005 | H9: SADAKA YA MAVUNO | I9: =C10 -> 666000 | J9: 31563200 | K9: =I9-J9 -> -30897200 | L9: =K9/J9 -> -0.97889948
A10: M0005 | B10: FUNGU LA KUMI | C10: ='Mapato 2023'!BD10 -> 666000 | G10: M0006 | H10: SADAKA YA PASAKA/kupaa | I10: =C11 -> 1898100 | J10: 8122300 | K10: =I10-J10 -> -6224200 | L10: =K10/J10 -> -0.76631004
A11: M0006 | B11: JUMUIYA | C11: ='Mapato 2023'!BD11 -> 1898100 | G11: M0007 | H11: SADAKA YA SHUKRANI AINA ZOTE | I11: =C26 -> 0 | J11: 3995000 | K11: =I11-J11 -> -3995000 | L11: =K11/J11 -> -1
A12: M0007 | B12: SHUKRANI YA CCB | C12: ='Mapato 2023'!BD12 -> 3842150 | G12: M0012 | H12: SHUKRANI YA CCB | I12: =C12 -> 3842150 | J12: 338350 | K12: =I12-J12 -> 3503800 | L12: =K12/J12 -> 10.355549
A13: M0008 | B13: SHUKRANI YA UBATIZO | C13: ='Mapato 2023'!BD14 -> 66000 | G13: M0008 | H13: SADAKA YA UBATIZO | I13: =C13 -> 66000 | J13: 486800 | K13: =I13-J13 -> -420800 | L13: =K13/J13 -> -0.86442071
A14: M0009 | B14: SADAKA MAALUM- KWAYA KUU | C14: ='Mapato 2023'!BD15 -> 20000 | G14: M0009 | H14: SHUKRANI YA KIPAIMARA | I14: =C24 -> 596100 | J14: 0 | K14: =I14-J14 -> 596100 | L14: =K14/J14 -> #DIV/0!
A15: M0010 | B15: SHUKRANI YA PASAKA | C15: ='Mapato 2023'!BD16 -> 0 | G15: M0010 | H15: SHUKRANI YA NDOA | I15: =#REF! -> #REF! | J15: 14525200 | K15: =I15-J15 -> #REF! | L15: =K15/J15 -> #REF!
A16: M0011 | B16: SADAKA YA ALHAMIS KUU | C16: ='Mapato 2023'!BD17 -> 17009650 | G16: M0011 | H16: SADAKA FUNGU LA KUMI | I16: =#REF! -> #REF! | J16: 218100 | K16: =I16-J16 -> #REF! | L16: =K16/J16 -> #REF!
A17: M0012 | B17: SADAKA YA JUMATANO/ MAJIVU | C17: ='Mapato 2023'!BD13 -> 357100 | G17: M0013 | H17: SADAKA YA JENGO | I17: =#REF! -> #REF! | J17: 139800 | K17: =I17-J17 -> #REF! | L17: =K17/J17 -> #REF!
A18: M0013 | B18: SADAKA YA IJUMAA KUU | C18: ='Mapato 2023'!BD18 -> 7617900 | G18: M0014 | H18: MICHANGO MBALIMBALI | I18: =C15+#REF! -> #REF! | J18: 855050 | K18: =I18-J18 -> #REF! | L18: =K18/J18 -> #REF!
A19: M0014 | B19: JENGO | C19: ='Mapato 2023'!BD19 -> 417400 | G19: M0015 | H19: SADAKA YA NYUMBA KWA NYUMBA | I19: =C16+C17+C18 -> 24984650 | J19: 293000 | K19: =I19-J19 -> 24691650 | L19: =K19/J19 -> 84.271843
A20: M0015 | B20: HARAMBEE YA NDANI | C20: ='Mapato 2023'!BD20 -> 6206750 | G20: M0016 | H20: SADAKA YA MORNING & EVENING GLORY | I20: =#REF! -> #REF! | J20: 53000 | K20: =I20-J20 -> #REF! | L20: =K20/J20 -> #REF!
A21: M0016 | B21: UNUNUZI WA KIWANJA | C21: ='Mapato 2023'!BD21 -> 0 | G21: M0017 | H21: HARAMBEE na mnada | I21: =#REF! -> #REF! | J21: 870100 | K21: =I21-J21 -> #REF! | L21: =K21/J21 -> #REF!
A22: M0017 | B22: SADAKA YA MWAKA MPYA | C22: ='Mapato 2023'!BD22 -> 35800 | G22: M0018 | H22: SADAKA YA MFUKO WA ELIMU | I22: =C22 -> 35800 | J22: 597650 | K22: =I22-J22 -> -561850 | L22: =K22/J22 -> -0.94009872
A23: M0018 | B23: UKWATA | C23: ='Mapato 2023'!BD23 -> 725350 | G23: M0019 | H23: SADAKA MAALUM- MAKAO MAKUU, VIJANA, KAZI ZA MISIONI,AKINA MAMA, VYAMA VYA INJILI, MSAMARIA MWEMA | I23: =C19 -> 417400 | J23: 12818300 | K23: =I23-J23 -> -12400900 | L23: =K23/J23 -> -0.96743718
A24: M0019 | B24: MAREJESHO YA AHADI NA JENGO | C24: ='Mapato 2023'!BD24 -> 596100 | G24: M0020 | H24: SADAKA ZA KAZI ZA UMOJA _JIMBO NA DAYOSISI | I24: =#REF! -> #REF! | J24: 3036950 | K24: =I24-J24 -> #REF! | L24: =K24/J24 -> #REF!
A25: M0020 | B25: SADAKA YA WAHITAJI | C25: ='Mapato 2023'!BD25 -> 0 | G25: M0021 | H25: SADAKA YA KRISMAS | I25: =C20 -> 6206750 | J25: 12051100 | K25: =I25-J25 -> -5844350 | L25: =K25/J25 -> -0.48496403
A26: M0021 | B26: SHUKRANI YA SIRI | C26: ='Mapato 2023'!BD26 -> 0 | G26: A.46 | H26: JUMLA | I26: =SUM(#REF!) -> #REF! | J26: =SUM(#REF!) -> #REF! | K26: =SUM(#REF!) -> #REF! | L26: =K26/J26 -> #REF!
B27: JUMLA (TSHS.) | C27: =SUM(C6:C26) -> 56139250

Sheet MALINGANISHO-MAPATO
D1: S/N | E1: SADAKA NA MICHANGO MBALIMBALI | F1: 2022 | G1: 2021 | H1: ONGEZEKO | I1: % YA Ongezeko/ Pungufu
H3: /PUNGUFU
F4: TSHS | G4: TSHS | H4: TSHS
D5: M01 | E5: SHUKRANI YA WIKI | F5: 14132050 | G5: 13136620 | H5: 995430 | I5: 0.075775199
D6: M02 | E6: AHADI | F6: 13995450 | G6: 12817580 | H6: 1177870 | I6: 0.091894882
D7: M03 | E7: SHULE YA JUMAPILI | F7: 2519250 | G7: 2159900 | H7: 359350 | I7: 0.16637344
D8: M04 | E8: SHUKRANI YA PEKEE | F8: 8504550 | G8: 4041600 | H8: 4462950 | I8: 1.1042533
D9: M05 | E9: FUNGU LA KUMI | F9: 42941500 | G9: 31563200 | H9: 11378300 | I9: 0.3604926
D10: M06 | E10: JUMUIYA | F10: 10878350 | G10: 8122300 | H10: 2756050 | I10: 0.33931891
D11: M07 | E11: SHUKRANI YA SIRI | F11: 3123150 | G11: 3995000 | H11: -871850 | I11: -0.21823529
D12: M08 | E12: SHUKRANI YA CCB | F12: 492150 | G12: 338350 | H12: 153800 | I12: 0.45455889
D13: M09 | E13: SHUKRANI YA UBATIZO | F13: 527100 | G13: 486800 | H13: 40300 | I13: 0.082785538
D14: M10 | E14: MAREJESHO YA AHADI NA JENGO | F14: 330000 | G14: 0 | H14: 330000 | I14: #DIV/0!
D15: M11 | E15: SADAKA YA MAVUNO | F15: 17284430 | G15: 14525200 | H15: 2759230 | I15: 0.18996158
D16: M12 | E16: SHUKRANI YA KIPAIMARA | F16: 0 | G16: 218100 | H16: -218100 | I16: -1
D17: M13 | E17: SHUKRANI YA WAMAMA | F17: 109100 | G17: 139800 | H17: -30700 | I17: -0.21959943
D18: M14 | E18: SHUKRANI YA PASAKA | F18: 1269800 | G18: 855050 | H18: 414750 | I18: 0.48505935
D19: M15 | E19: SADAKA YA ALHAMISI KUU/IJUMAA KUU NA JUMATANO | F19: 345600 | G19: 293000 | H19: 52600 | I19: 0.17952218
D20: M16 | E20: SHUKRANI YA NDOA | F20: 0 | G20: 53000 | H20: -53000 | I20: -1
D21: M17 | E21: SHUKRANI YA KRISIMASI | F21: 700600 | G21: 870100 | H21: -169500 | I21: -0.19480519
D22: M18 | E22: SADAKA YA MWAKA MPYA | F22: 679450 | G22: 597650 | H22: 81800 | I22: 0.13686941
D23: M19 | E23: JENGO | F23: 13506050 | G23: 12818300 | H23: 687750 | I23: 0.053653761
D24: M20 | E24: MAREJESHO YA MINADA | F24: 4105300 | G24: 3036950 | H24: 1068350 | I24: 0.35178386
D25: M21 | E25: HARAMBEE YA NDANI | F25: 13721800 | G25: 12051100 | H25: 1670700 | I25: 0.13863465
D26: M22 | E26: UNUNUZI WA KIWANJA | F26: 0 | G26: 587850 | H26: -587850 | I26: -1
... D36: M32 | E36: SADAKA YA UKWATA/1DAYOSISI | F36: 0 | G36: 151600 | H36: -151600 | I36: -1
D37: M33 | E37: SADAKA Y AMALIMBUKO | F37: 0 | G37: 0 | H37: 0 | I37: #DIV/0!
D38: M34 | E38: CCT | F38: 78200 | G38: 91000 | H38: -12800 | I38: -0.14065934
D39: M35 | E39: MFUKO WA ELIMU | F39: 1214050 | G39: 1035250 | H39: 178800 | I39: 0.17271191
D40: M36 | E40: WALIMU | F40: 0 | G40: 60000 | H40: -60000 | I40: -1
D41: M37 | E41: UNUNUZI WA GITAA | F41: 0 | G41: 2330000 | H41: -2330000 | I41: -1
D42: M38 | E42: SADAKA YA MBEGU | F42: 0 | G42: 10000 | H42: -10000 | I42: -1
D43: M39 | E43: KKKT | F43: 103800 | G43: 0 | H43: 103800 | I43: 1
D44: M40 | E44: MALIMBUKO | F44: 390000 | G44: 0 | H44: 390000 | I44: 1
D45: M41 | E45: HARAMBEE YA NDANI MIKAELI NA WATOTO | F45: 1657800 | G45: 0 | H45: 1657800 | I45: 1
D46: M42 | E46: KAWAIDA/COLECT | F46: 619450 | G46: 0 | H46: 619450 | I46: 1
D47: M43 | E47: SADAKA YA USIKU MTAKATIFU | F47: 21100 | G47: 0 | H47: 21100 | I47: 1
D48: M44 | E48: HARAMBEE YA NDANI UJENZI | F48: 13474120 | G48: 0 | H48: 13598650 | I48: 1
D49: M45 | E49: JUMLA YA MAPATO KWA NJIA YA SADAKA | F49: =SUM(F5:F48) -> 170082350 | G49: 130877250 | H49: 39365630 | I49: 0.30078283
D50: M46 | E50: MKOPO SACCOS | F50: 25000000 | G50: 43000000 | H50: -18000000 | I50: -0.41860465
...

Sheet Sheet1
C2: B.01 | D2: Nauli Mbalimbali( Watumishi, Vikundi,Bible study, Bank) | F2: 6070000 | G2: =E2-F2 -> -6070000 | H2: =G2/F2 -> -1
C3: B.02 | D3: Mishahara na Posho Mbalimbali | E3: 31949675 | F3: 31949675 | G3: =E3-F3 -> 0 | H3: =G3/F3 -> 0
C4: B.03 | D4: Malipo ya NSSF (Mfuko wa hifadhi ya Jamii) | E4: 2034180 | F4: 2034180 | G4: =E4-F4 -> 0 | H4: =G4/F4 -> 0
C5: B.04 | D5: Matumizi -Mtaa- ( umeme,Gas,Service ya Generator , usafi,matengenezo, vyombo, Vifaa vya Madhabahuni,Maji ya watoto,Bill za Maji, Bahasha za Ahadi na Jengo pamoja na Vyombo vya Madhabahu) | E5: 13743700 | F5: 13743700 | G5: =E5-F5 -> 0 | H5: =G5/F5 -> 0
C6: B.05 | D6: 8% ya Jimbo | E6: 5977798 | F6: 5977798 | G6: =E6-F6 -> 0 | H6: =G6/F6 -> 0
C7: B.06 | D7: Stationery | E7: 292000 | F7: 292000 | G7: =E7-F7 -> 0 | H7: =G7/F7 -> 0
C8: B.08 | D8: Gharama za Vikao/Semina/kongamano na Mikesha | E8: 7104500 | F8: 7104500 | G8: =E8-F8 -> 0 | H8: =G8/F8 -> 0
C9: B.09 | D9: Computer na vifaa Vyake | G9: =E9-F9 -> 0 | H9: =G9/F9 -> #DIV/0!
C10: B.11 | D10: Michael na Watoto /Safari za Watoto | E10: 1795500 | F10: 1795500 | G10: =E10-F10 -> 0 | H10: =G10/F10 -> 0
C11: B.13 | D11: Wahitaji, Yatima, Wajane, Wagonjwa na walimu wa Sunday school | E11: 5916800 | F11: 5916800 | G11: =E11-F11 -> 0 | H11: =G11/F11 -> 0
C12: B.14 | D12: Manunuzi ya Vyombo vya Mziki | E12: 1950000 | F12: 1950000 | G12: =E12-F12 -> 0 | H12: =G12/F12 -> 0
C13: B.15 | D13: Michango ya Dayosis / Jimbo na Mbwawa | E13: 933400 | F13: 933400 | G13: =E13-F13 -> 0 | H13: =G13/F13 -> 0
C14: B.16 | D14: Rambi Rambi na Misiba | E14: 1250000 | F14: 1250000 | G14: =E14-F14 -> 0 | H14: =G14/F14 -> 0
C15: B.17 | D15: Ukwata | G15: =E15-F15 -> 0 | H15: =G15/F15 -> #DIV/0!
C16: B.18 | D16: Waimbaji binafsi | E16: 400000 | F16: 400000 | G16: =E16-F16 -> 0 | H16: =G16/F16 -> 0
C17: B.19 | D17: JUMLA NDOGO | E17: =SUM(E2:E16) -> 73347553 | F17: 79417553 | G17: 79417553 | H17: 79417553
C20: B.21 | D20: B.MATUMIZI A UJENZI | G20: -
C21: B.22 | D21: Ukarabati wa Office kuweka Tiles ,Ukarabati wa choo na Jiko na kuhamisha nguzo ya umeme | E21: 10730758 | F21: 19196600 | G21: -10730758 | H21: -0.56
C22: B.23 | D22: Gharama za Mafundi | E22: 1855000 | F22: 4710000 | G22: -2855000 | H22: -0.61
C23: B.24 | D23: Usafiri wa vifaa vya ujenzi | E23: 170000 | F23: 636000 | G23: -466000 | H23: -0.73
C24: B.25 | D24: Ujenzi/Ukarabati wa Darasa la Watoto | E24: 7644000 | F24: 500000 | G24: 7144000 | H24: 14.29
C25: B.02 | D25: Kuingiza umeme Kwenye Jengo | F25: 515618 | G25: -515618 | H25: -1
C26: B.28 | D26: Ramani 3D | E26: - | F26: 2100000 | G26: -2100000 | H26: -1
C27: B.29 | D27: Matengenezo Milango ya Ofisi | E27: - | F27: 2225000 | G27: -2225000 | H27: -1
C28: B.30 | D28: Kuchangia Ujenzi wa Duka la Kwaya kuu | E28: - | F28: 1100000 | G28: -1100000 | H28: -1
C29: B.31 | D29: Matengenezo ya Barabara | E29: 1431000 | F29: 3740000 | G29: -2309000 | H29: -0.62
C30: B.32 | D30: Gharama za uandaaji wa Harambee | F30: 2034661 | G30: -2034661 | H30: -1
C31: B.39 | D31: Daraja | E31: 9406000 | F31: - | G31: 9406000 | H31: 1
C32: B.33 | D32: JUMLA NDOGO | E32: 28971842 | F32: 37757879 | G32: -8786037 | H32: -0.23
C33: B.34 | D33: Bank Charges /Gharama za Benki | E33: 186883 | F33: 407930 | G33: -221047 | H33: -0.54
C34: B.35 | D34: JUMLA YA MATUMIZI KWA MWAKA 2020 | E34: 108576278 | F34: 115613157 | G34: -7036879 | H34: -0.06
C35: B.36 | D35: Madeni | E35: - | F35: 3350000 | G35: -3350000 | H35: -1
C36: B.37 | D36: Uwekezaji Saccoss | E36: 4400000 | F36: 21300000 | G36: -16900000 | H36: -0.79
C37: B.38 | D37: JUMLA YA MATUMIZI KWA MWAKA 2020 | E37: 112976278 | F37: 140263157 | G37: -27286879 | H37: -0.19
